2025-01-26 09:03:38,019 - app.components.routers.parse - ERROR - 删除记录失败 record_id: 6794773b8cd6534bed5c55c9, 错误: 404: Record not found
Traceback (most recent call last):
  File "D:\Code\Python\LLM-Kit\app\components\routers\parse.py", line 754, in delete_record
    raise HTTPException(status_code=404, detail="Record not found")
fastapi.exceptions.HTTPException: 404: Record not found
2025-01-26 09:03:55,069 - app.components.routers.parse - ERROR - 删除文件失败 file_id: 679479eb7e25968cd63194d9, 错误: 404: File not found
Traceback (most recent call last):
  File "D:\Code\Python\LLM-Kit\app\components\routers\parse.py", line 729, in delete_file
    raise HTTPException(status_code=404, detail="File not found")
fastapi.exceptions.HTTPException: 404: File not found
2025-01-26 09:05:20,257 - app.components.routers.to_tex - ERROR - 删除LaTeX记录失败 record_id: 6794e06350fef7924629f762, 错误: 404: Record not found
Traceback (most recent call last):
  File "D:\Code\Python\LLM-Kit\app\components\routers\to_tex.py", line 133, in delete_tex_record
    raise HTTPException(status_code=404, detail="Record not found")
fastapi.exceptions.HTTPException: 404: Record not found
2025-01-26 11:02:34,741 - app.components.routers.parse - ERROR - 解析文件失败 file_id: 6795a56f4a09e7157845e924, 错误: Parse content failed: [WinError 183] 当文件已存在时，无法创建该文件。: './parsed_files\\parsed_file\\tmprrar_vb8.txt' -> './parsed_files\\parsed_file\\ceshi.txt_parsed.txt'
Traceback (most recent call last):
  File "D:\Code\Python\LLM-Kit\app\components\services\parse_service.py", line 258, in parse_content
    os.rename(parsed_file_path, new_file_path)
FileExistsError: [WinError 183] 当文件已存在时，无法创建该文件。: './parsed_files\\parsed_file\\tmprrar_vb8.txt' -> './parsed_files\\parsed_file\\ceshi.txt_parsed.txt'

During handling of the above exception, another exception occurred:

Traceback (most recent call last):
  File "D:\Code\Python\LLM-Kit\app\components\routers\parse.py", line 381, in parse_specific_file
    raise e
  File "D:\Code\Python\LLM-Kit\app\components\routers\parse.py", line 343, in parse_specific_file
    parse_result = await service.parse_content(
  File "D:\Code\Python\LLM-Kit\app\components\services\parse_service.py", line 302, in parse_content
    raise Exception(f"Parse content failed: {str(e)}")
Exception: Parse content failed: [WinError 183] 当文件已存在时，无法创建该文件。: './parsed_files\\parsed_file\\tmprrar_vb8.txt' -> './parsed_files\\parsed_file\\ceshi.txt_parsed.txt'
2025-01-26 11:02:37,364 - app.components.routers.parse - ERROR - 解析文件失败 file_id: 6795a56f4a09e7157845e924, 错误: Parse content failed: [WinError 183] 当文件已存在时，无法创建该文件。: './parsed_files\\parsed_file\\tmpgx2hk66k.txt' -> './parsed_files\\parsed_file\\ceshi.txt_parsed.txt'
Traceback (most recent call last):
  File "D:\Code\Python\LLM-Kit\app\components\services\parse_service.py", line 258, in parse_content
    os.rename(parsed_file_path, new_file_path)
FileExistsError: [WinError 183] 当文件已存在时，无法创建该文件。: './parsed_files\\parsed_file\\tmpgx2hk66k.txt' -> './parsed_files\\parsed_file\\ceshi.txt_parsed.txt'

During handling of the above exception, another exception occurred:

Traceback (most recent call last):
  File "D:\Code\Python\LLM-Kit\app\components\routers\parse.py", line 381, in parse_specific_file
    raise e
  File "D:\Code\Python\LLM-Kit\app\components\routers\parse.py", line 343, in parse_specific_file
    parse_result = await service.parse_content(
  File "D:\Code\Python\LLM-Kit\app\components\services\parse_service.py", line 302, in parse_content
    raise Exception(f"Parse content failed: {str(e)}")
Exception: Parse content failed: [WinError 183] 当文件已存在时，无法创建该文件。: './parsed_files\\parsed_file\\tmpgx2hk66k.txt' -> './parsed_files\\parsed_file\\ceshi.txt_parsed.txt'
2025-01-26 11:02:37,850 - app.components.routers.parse - ERROR - 解析文件失败 file_id: 6795a56f4a09e7157845e924, 错误: Parse content failed: [WinError 183] 当文件已存在时，无法创建该文件。: './parsed_files\\parsed_file\\tmpk_xgvvui.txt' -> './parsed_files\\parsed_file\\ceshi.txt_parsed.txt'
Traceback (most recent call last):
  File "D:\Code\Python\LLM-Kit\app\components\services\parse_service.py", line 258, in parse_content
    os.rename(parsed_file_path, new_file_path)
FileExistsError: [WinError 183] 当文件已存在时，无法创建该文件。: './parsed_files\\parsed_file\\tmpk_xgvvui.txt' -> './parsed_files\\parsed_file\\ceshi.txt_parsed.txt'

During handling of the above exception, another exception occurred:

Traceback (most recent call last):
  File "D:\Code\Python\LLM-Kit\app\components\routers\parse.py", line 381, in parse_specific_file
    raise e
  File "D:\Code\Python\LLM-Kit\app\components\routers\parse.py", line 343, in parse_specific_file
    parse_result = await service.parse_content(
  File "D:\Code\Python\LLM-Kit\app\components\services\parse_service.py", line 302, in parse_content
    raise Exception(f"Parse content failed: {str(e)}")
Exception: Parse content failed: [WinError 183] 当文件已存在时，无法创建该文件。: './parsed_files\\parsed_file\\tmpk_xgvvui.txt' -> './parsed_files\\parsed_file\\ceshi.txt_parsed.txt'
2025-01-26 11:02:38,226 - app.components.routers.parse - ERROR - 解析文件失败 file_id: 6795a56f4a09e7157845e924, 错误: Parse content failed: [WinError 183] 当文件已存在时，无法创建该文件。: './parsed_files\\parsed_file\\tmpv5ohru8c.txt' -> './parsed_files\\parsed_file\\ceshi.txt_parsed.txt'
Traceback (most recent call last):
  File "D:\Code\Python\LLM-Kit\app\components\services\parse_service.py", line 258, in parse_content
    os.rename(parsed_file_path, new_file_path)
FileExistsError: [WinError 183] 当文件已存在时，无法创建该文件。: './parsed_files\\parsed_file\\tmpv5ohru8c.txt' -> './parsed_files\\parsed_file\\ceshi.txt_parsed.txt'

During handling of the above exception, another exception occurred:

Traceback (most recent call last):
  File "D:\Code\Python\LLM-Kit\app\components\routers\parse.py", line 381, in parse_specific_file
    raise e
  File "D:\Code\Python\LLM-Kit\app\components\routers\parse.py", line 343, in parse_specific_file
    parse_result = await service.parse_content(
  File "D:\Code\Python\LLM-Kit\app\components\services\parse_service.py", line 302, in parse_content
    raise Exception(f"Parse content failed: {str(e)}")
Exception: Parse content failed: [WinError 183] 当文件已存在时，无法创建该文件。: './parsed_files\\parsed_file\\tmpv5ohru8c.txt' -> './parsed_files\\parsed_file\\ceshi.txt_parsed.txt'
2025-01-26 11:03:42,163 - app.components.routers.parse - ERROR - 解析文件失败 file_id: 6795a56f4a09e7157845e924, 错误: Parse content failed: [WinError 183] 当文件已存在时，无法创建该文件。: './parsed_files\\parsed_file\\tmphye_f0rr.txt' -> './parsed_files\\parsed_file\\ceshi.txt_parsed.txt'
Traceback (most recent call last):
  File "D:\Code\Python\LLM-Kit\app\components\services\parse_service.py", line 258, in parse_content
    os.rename(parsed_file_path, new_file_path)
FileExistsError: [WinError 183] 当文件已存在时，无法创建该文件。: './parsed_files\\parsed_file\\tmphye_f0rr.txt' -> './parsed_files\\parsed_file\\ceshi.txt_parsed.txt'

During handling of the above exception, another exception occurred:

Traceback (most recent call last):
  File "D:\Code\Python\LLM-Kit\app\components\routers\parse.py", line 381, in parse_specific_file
    raise e
  File "D:\Code\Python\LLM-Kit\app\components\routers\parse.py", line 343, in parse_specific_file
    parse_result = await service.parse_content(
  File "D:\Code\Python\LLM-Kit\app\components\services\parse_service.py", line 302, in parse_content
    raise Exception(f"Parse content failed: {str(e)}")
Exception: Parse content failed: [WinError 183] 当文件已存在时，无法创建该文件。: './parsed_files\\parsed_file\\tmphye_f0rr.txt' -> './parsed_files\\parsed_file\\ceshi.txt_parsed.txt'
2025-01-26 11:06:36,321 - app.components.routers.parse - ERROR - 解析文件失败 file_id: 67958b7e555fd5df1912ebec, 错误: Parse content failed: [WinError 183] 当文件已存在时，无法创建该文件。: './parsed_files\\parsed_file\\tmpkihjslj6.txt' -> './parsed_files\\parsed_file\\ttt_parsed.txt'
Traceback (most recent call last):
  File "D:\Code\Python\LLM-Kit\app\components\services\parse_service.py", line 258, in parse_content
    os.rename(parsed_file_path, new_file_path)
FileExistsError: [WinError 183] 当文件已存在时，无法创建该文件。: './parsed_files\\parsed_file\\tmpkihjslj6.txt' -> './parsed_files\\parsed_file\\ttt_parsed.txt'

During handling of the above exception, another exception occurred:

Traceback (most recent call last):
  File "D:\Code\Python\LLM-Kit\app\components\routers\parse.py", line 381, in parse_specific_file
    raise e
  File "D:\Code\Python\LLM-Kit\app\components\routers\parse.py", line 343, in parse_specific_file
    parse_result = await service.parse_content(
  File "D:\Code\Python\LLM-Kit\app\components\services\parse_service.py", line 302, in parse_content
    raise Exception(f"Parse content failed: {str(e)}")
Exception: Parse content failed: [WinError 183] 当文件已存在时，无法创建该文件。: './parsed_files\\parsed_file\\tmpkihjslj6.txt' -> './parsed_files\\parsed_file\\ttt_parsed.txt'
2025-01-26 11:06:40,611 - app.components.routers.parse - ERROR - 解析文件失败 file_id: 67958b7e555fd5df1912ebec, 错误: Parse content failed: [WinError 183] 当文件已存在时，无法创建该文件。: './parsed_files\\parsed_file\\tmp9wrqgkhm.txt' -> './parsed_files\\parsed_file\\ttt_parsed.txt'
Traceback (most recent call last):
  File "D:\Code\Python\LLM-Kit\app\components\services\parse_service.py", line 258, in parse_content
    os.rename(parsed_file_path, new_file_path)
FileExistsError: [WinError 183] 当文件已存在时，无法创建该文件。: './parsed_files\\parsed_file\\tmp9wrqgkhm.txt' -> './parsed_files\\parsed_file\\ttt_parsed.txt'

During handling of the above exception, another exception occurred:

Traceback (most recent call last):
  File "D:\Code\Python\LLM-Kit\app\components\routers\parse.py", line 381, in parse_specific_file
    raise e
  File "D:\Code\Python\LLM-Kit\app\components\routers\parse.py", line 343, in parse_specific_file
    parse_result = await service.parse_content(
  File "D:\Code\Python\LLM-Kit\app\components\services\parse_service.py", line 302, in parse_content
    raise Exception(f"Parse content failed: {str(e)}")
Exception: Parse content failed: [WinError 183] 当文件已存在时，无法创建该文件。: './parsed_files\\parsed_file\\tmp9wrqgkhm.txt' -> './parsed_files\\parsed_file\\ttt_parsed.txt'
2025-01-26 11:10:19,682 - app.components.routers.parse - ERROR - 解析文件失败 file_id: 6795a6fb4a09e7157845e93e, 错误: Parse content failed: [WinError 183] 当文件已存在时，无法创建该文件。: './parsed_files\\parsed_file\\tmpi6nd7r0p.txt' -> './parsed_files\\parsed_file\\ce3shi.txt_parsed.txt'
Traceback (most recent call last):
  File "D:\Code\Python\LLM-Kit\app\components\services\parse_service.py", line 258, in parse_content
    os.rename(parsed_file_path, new_file_path)
FileExistsError: [WinError 183] 当文件已存在时，无法创建该文件。: './parsed_files\\parsed_file\\tmpi6nd7r0p.txt' -> './parsed_files\\parsed_file\\ce3shi.txt_parsed.txt'

During handling of the above exception, another exception occurred:

Traceback (most recent call last):
  File "D:\Code\Python\LLM-Kit\app\components\routers\parse.py", line 381, in parse_specific_file
    raise e
  File "D:\Code\Python\LLM-Kit\app\components\routers\parse.py", line 343, in parse_specific_file
    parse_result = await service.parse_content(
  File "D:\Code\Python\LLM-Kit\app\components\services\parse_service.py", line 302, in parse_content
    raise Exception(f"Parse content failed: {str(e)}")
Exception: Parse content failed: [WinError 183] 当文件已存在时，无法创建该文件。: './parsed_files\\parsed_file\\tmpi6nd7r0p.txt' -> './parsed_files\\parsed_file\\ce3shi.txt_parsed.txt'
2025-01-26 11:11:19,388 - app.components.routers.parse - ERROR - 解析文件失败 file_id: 6795a6fb4a09e7157845e93e, 错误: Parse content failed: [WinError 183] 当文件已存在时，无法创建该文件。: './parsed_files\\parsed_file\\tmpqn4khm4s.txt' -> './parsed_files\\parsed_file\\ce3shi.txt_parsed.txt'
Traceback (most recent call last):
  File "D:\Code\Python\LLM-Kit\app\components\services\parse_service.py", line 258, in parse_content
    os.rename(parsed_file_path, new_file_path)
FileExistsError: [WinError 183] 当文件已存在时，无法创建该文件。: './parsed_files\\parsed_file\\tmpqn4khm4s.txt' -> './parsed_files\\parsed_file\\ce3shi.txt_parsed.txt'

During handling of the above exception, another exception occurred:

Traceback (most recent call last):
  File "D:\Code\Python\LLM-Kit\app\components\routers\parse.py", line 381, in parse_specific_file
    raise e
  File "D:\Code\Python\LLM-Kit\app\components\routers\parse.py", line 343, in parse_specific_file
    parse_result = await service.parse_content(
  File "D:\Code\Python\LLM-Kit\app\components\services\parse_service.py", line 302, in parse_content
    raise Exception(f"Parse content failed: {str(e)}")
Exception: Parse content failed: [WinError 183] 当文件已存在时，无法创建该文件。: './parsed_files\\parsed_file\\tmpqn4khm4s.txt' -> './parsed_files\\parsed_file\\ce3shi.txt_parsed.txt'
2025-01-26 11:11:21,206 - app.components.routers.parse - ERROR - 解析文件失败 file_id: 6795a6fb4a09e7157845e93e, 错误: Parse content failed: [WinError 183] 当文件已存在时，无法创建该文件。: './parsed_files\\parsed_file\\tmplhbvxol9.txt' -> './parsed_files\\parsed_file\\ce3shi.txt_parsed.txt'
Traceback (most recent call last):
  File "D:\Code\Python\LLM-Kit\app\components\services\parse_service.py", line 258, in parse_content
    os.rename(parsed_file_path, new_file_path)
FileExistsError: [WinError 183] 当文件已存在时，无法创建该文件。: './parsed_files\\parsed_file\\tmplhbvxol9.txt' -> './parsed_files\\parsed_file\\ce3shi.txt_parsed.txt'

During handling of the above exception, another exception occurred:

Traceback (most recent call last):
  File "D:\Code\Python\LLM-Kit\app\components\routers\parse.py", line 381, in parse_specific_file
    raise e
  File "D:\Code\Python\LLM-Kit\app\components\routers\parse.py", line 343, in parse_specific_file
    parse_result = await service.parse_content(
  File "D:\Code\Python\LLM-Kit\app\components\services\parse_service.py", line 302, in parse_content
    raise Exception(f"Parse content failed: {str(e)}")
Exception: Parse content failed: [WinError 183] 当文件已存在时，无法创建该文件。: './parsed_files\\parsed_file\\tmplhbvxol9.txt' -> './parsed_files\\parsed_file\\ce3shi.txt_parsed.txt'
2025-01-26 11:11:21,730 - app.components.routers.parse - ERROR - 解析文件失败 file_id: 6795a6fb4a09e7157845e93e, 错误: Parse content failed: [WinError 183] 当文件已存在时，无法创建该文件。: './parsed_files\\parsed_file\\tmpxaulmv1z.txt' -> './parsed_files\\parsed_file\\ce3shi.txt_parsed.txt'
Traceback (most recent call last):
  File "D:\Code\Python\LLM-Kit\app\components\services\parse_service.py", line 258, in parse_content
    os.rename(parsed_file_path, new_file_path)
FileExistsError: [WinError 183] 当文件已存在时，无法创建该文件。: './parsed_files\\parsed_file\\tmpxaulmv1z.txt' -> './parsed_files\\parsed_file\\ce3shi.txt_parsed.txt'

During handling of the above exception, another exception occurred:

Traceback (most recent call last):
  File "D:\Code\Python\LLM-Kit\app\components\routers\parse.py", line 381, in parse_specific_file
    raise e
  File "D:\Code\Python\LLM-Kit\app\components\routers\parse.py", line 343, in parse_specific_file
    parse_result = await service.parse_content(
  File "D:\Code\Python\LLM-Kit\app\components\services\parse_service.py", line 302, in parse_content
    raise Exception(f"Parse content failed: {str(e)}")
Exception: Parse content failed: [WinError 183] 当文件已存在时，无法创建该文件。: './parsed_files\\parsed_file\\tmpxaulmv1z.txt' -> './parsed_files\\parsed_file\\ce3shi.txt_parsed.txt'
2025-01-26 11:11:22,112 - app.components.routers.parse - ERROR - 解析文件失败 file_id: 6795a6fb4a09e7157845e93e, 错误: Parse content failed: [WinError 183] 当文件已存在时，无法创建该文件。: './parsed_files\\parsed_file\\tmpf221r57r.txt' -> './parsed_files\\parsed_file\\ce3shi.txt_parsed.txt'
Traceback (most recent call last):
  File "D:\Code\Python\LLM-Kit\app\components\services\parse_service.py", line 258, in parse_content
    os.rename(parsed_file_path, new_file_path)
FileExistsError: [WinError 183] 当文件已存在时，无法创建该文件。: './parsed_files\\parsed_file\\tmpf221r57r.txt' -> './parsed_files\\parsed_file\\ce3shi.txt_parsed.txt'

During handling of the above exception, another exception occurred:

Traceback (most recent call last):
  File "D:\Code\Python\LLM-Kit\app\components\routers\parse.py", line 381, in parse_specific_file
    raise e
  File "D:\Code\Python\LLM-Kit\app\components\routers\parse.py", line 343, in parse_specific_file
    parse_result = await service.parse_content(
  File "D:\Code\Python\LLM-Kit\app\components\services\parse_service.py", line 302, in parse_content
    raise Exception(f"Parse content failed: {str(e)}")
Exception: Parse content failed: [WinError 183] 当文件已存在时，无法创建该文件。: './parsed_files\\parsed_file\\tmpf221r57r.txt' -> './parsed_files\\parsed_file\\ce3shi.txt_parsed.txt'
2025-01-26 11:11:22,408 - app.components.routers.parse - ERROR - 解析文件失败 file_id: 6795a6fb4a09e7157845e93e, 错误: Parse content failed: [WinError 183] 当文件已存在时，无法创建该文件。: './parsed_files\\parsed_file\\tmp6m1qel4_.txt' -> './parsed_files\\parsed_file\\ce3shi.txt_parsed.txt'
Traceback (most recent call last):
  File "D:\Code\Python\LLM-Kit\app\components\services\parse_service.py", line 258, in parse_content
    os.rename(parsed_file_path, new_file_path)
FileExistsError: [WinError 183] 当文件已存在时，无法创建该文件。: './parsed_files\\parsed_file\\tmp6m1qel4_.txt' -> './parsed_files\\parsed_file\\ce3shi.txt_parsed.txt'

During handling of the above exception, another exception occurred:

Traceback (most recent call last):
  File "D:\Code\Python\LLM-Kit\app\components\routers\parse.py", line 381, in parse_specific_file
    raise e
  File "D:\Code\Python\LLM-Kit\app\components\routers\parse.py", line 343, in parse_specific_file
    parse_result = await service.parse_content(
  File "D:\Code\Python\LLM-Kit\app\components\services\parse_service.py", line 302, in parse_content
    raise Exception(f"Parse content failed: {str(e)}")
Exception: Parse content failed: [WinError 183] 当文件已存在时，无法创建该文件。: './parsed_files\\parsed_file\\tmp6m1qel4_.txt' -> './parsed_files\\parsed_file\\ce3shi.txt_parsed.txt'
2025-01-26 11:11:22,671 - app.components.routers.parse - ERROR - 解析文件失败 file_id: 6795a6fb4a09e7157845e93e, 错误: Parse content failed: [WinError 183] 当文件已存在时，无法创建该文件。: './parsed_files\\parsed_file\\tmp6phmbe23.txt' -> './parsed_files\\parsed_file\\ce3shi.txt_parsed.txt'
Traceback (most recent call last):
  File "D:\Code\Python\LLM-Kit\app\components\services\parse_service.py", line 258, in parse_content
    os.rename(parsed_file_path, new_file_path)
FileExistsError: [WinError 183] 当文件已存在时，无法创建该文件。: './parsed_files\\parsed_file\\tmp6phmbe23.txt' -> './parsed_files\\parsed_file\\ce3shi.txt_parsed.txt'

During handling of the above exception, another exception occurred:

Traceback (most recent call last):
  File "D:\Code\Python\LLM-Kit\app\components\routers\parse.py", line 381, in parse_specific_file
    raise e
  File "D:\Code\Python\LLM-Kit\app\components\routers\parse.py", line 343, in parse_specific_file
    parse_result = await service.parse_content(
  File "D:\Code\Python\LLM-Kit\app\components\services\parse_service.py", line 302, in parse_content
    raise Exception(f"Parse content failed: {str(e)}")
Exception: Parse content failed: [WinError 183] 当文件已存在时，无法创建该文件。: './parsed_files\\parsed_file\\tmp6phmbe23.txt' -> './parsed_files\\parsed_file\\ce3shi.txt_parsed.txt'
2025-01-26 11:11:22,990 - app.components.routers.parse - ERROR - 解析文件失败 file_id: 6795a6fb4a09e7157845e93e, 错误: Parse content failed: [WinError 183] 当文件已存在时，无法创建该文件。: './parsed_files\\parsed_file\\tmpty32rf9l.txt' -> './parsed_files\\parsed_file\\ce3shi.txt_parsed.txt'
Traceback (most recent call last):
  File "D:\Code\Python\LLM-Kit\app\components\services\parse_service.py", line 258, in parse_content
    os.rename(parsed_file_path, new_file_path)
FileExistsError: [WinError 183] 当文件已存在时，无法创建该文件。: './parsed_files\\parsed_file\\tmpty32rf9l.txt' -> './parsed_files\\parsed_file\\ce3shi.txt_parsed.txt'

During handling of the above exception, another exception occurred:

Traceback (most recent call last):
  File "D:\Code\Python\LLM-Kit\app\components\routers\parse.py", line 381, in parse_specific_file
    raise e
  File "D:\Code\Python\LLM-Kit\app\components\routers\parse.py", line 343, in parse_specific_file
    parse_result = await service.parse_content(
  File "D:\Code\Python\LLM-Kit\app\components\services\parse_service.py", line 302, in parse_content
    raise Exception(f"Parse content failed: {str(e)}")
Exception: Parse content failed: [WinError 183] 当文件已存在时，无法创建该文件。: './parsed_files\\parsed_file\\tmpty32rf9l.txt' -> './parsed_files\\parsed_file\\ce3shi.txt_parsed.txt'
2025-01-26 11:13:39,589 - app.components.routers.parse - ERROR - 解析文件失败 file_id: 6795a80b4a09e7157845e959, 错误: Parse content failed: [WinError 183] 当文件已存在时，无法创建该文件。: './parsed_files\\parsed_file\\tmp62xwlahm.txt' -> './parsed_files\\parsed_file\\ce3s5hi.txt_parsed.txt'
Traceback (most recent call last):
  File "D:\Code\Python\LLM-Kit\app\components\services\parse_service.py", line 258, in parse_content
    os.rename(parsed_file_path, new_file_path)
FileExistsError: [WinError 183] 当文件已存在时，无法创建该文件。: './parsed_files\\parsed_file\\tmp62xwlahm.txt' -> './parsed_files\\parsed_file\\ce3s5hi.txt_parsed.txt'

During handling of the above exception, another exception occurred:

Traceback (most recent call last):
  File "D:\Code\Python\LLM-Kit\app\components\routers\parse.py", line 381, in parse_specific_file
    raise e
  File "D:\Code\Python\LLM-Kit\app\components\routers\parse.py", line 343, in parse_specific_file
    parse_result = await service.parse_content(
  File "D:\Code\Python\LLM-Kit\app\components\services\parse_service.py", line 302, in parse_content
    raise Exception(f"Parse content failed: {str(e)}")
Exception: Parse content failed: [WinError 183] 当文件已存在时，无法创建该文件。: './parsed_files\\parsed_file\\tmp62xwlahm.txt' -> './parsed_files\\parsed_file\\ce3s5hi.txt_parsed.txt'
2025-01-26 14:52:38,524 - app.components.routers.parse - ERROR - 解析文件失败: Parse content failed: [WinError 183] 当文件已存在时，无法创建该文件。: 'result/parsed_file\\tmplcx30ncq.txt' -> 'result/parsed_file\\test_parsed.txt'
Traceback (most recent call last):
  File "D:\problem_solve\Python\Final_LLM\LLM-Kit\app\components\services\parse_service.py", line 258, in parse_content
    os.rename(parsed_file_path, new_file_path)
FileExistsError: [WinError 183] 当文件已存在时，无法创建该文件。: 'result/parsed_file\\tmplcx30ncq.txt' -> 'result/parsed_file\\test_parsed.txt'

During handling of the above exception, another exception occurred:

Traceback (most recent call last):
  File "D:\problem_solve\Python\Final_LLM\LLM-Kit\app\components\routers\parse.py", line 219, in parse_file
    raise e
  File "D:\problem_solve\Python\Final_LLM\LLM-Kit\app\components\routers\parse.py", line 178, in parse_file
    result = await service.parse_content(
             ^^^^^^^^^^^^^^^^^^^^^^^^^^^^
  File "D:\problem_solve\Python\Final_LLM\LLM-Kit\app\components\services\parse_service.py", line 302, in parse_content
    raise Exception(f"Parse content failed: {str(e)}")
Exception: Parse content failed: [WinError 183] 当文件已存在时，无法创建该文件。: 'result/parsed_file\\tmplcx30ncq.txt' -> 'result/parsed_file\\test_parsed.txt'
2025-01-26 14:53:00,900 - app.components.routers.parse - ERROR - 解析文件失败 file_id: 6795da971e957ef81ff27010, 错误: Parse content failed: [WinError 183] 当文件已存在时，无法创建该文件。: './parsed_files\\parsed_file\\tmpdv65ytd6.txt' -> './parsed_files\\parsed_file\\test003_parsed.txt'
Traceback (most recent call last):
  File "D:\problem_solve\Python\Final_LLM\LLM-Kit\app\components\services\parse_service.py", line 258, in parse_content
    os.rename(parsed_file_path, new_file_path)
FileExistsError: [WinError 183] 当文件已存在时，无法创建该文件。: './parsed_files\\parsed_file\\tmpdv65ytd6.txt' -> './parsed_files\\parsed_file\\test003_parsed.txt'

During handling of the above exception, another exception occurred:

Traceback (most recent call last):
  File "D:\problem_solve\Python\Final_LLM\LLM-Kit\app\components\routers\parse.py", line 405, in parse_specific_file
    raise e
  File "D:\problem_solve\Python\Final_LLM\LLM-Kit\app\components\routers\parse.py", line 367, in parse_specific_file
    parse_result = await service.parse_content(
                   ^^^^^^^^^^^^^^^^^^^^^^^^^^^^
  File "D:\problem_solve\Python\Final_LLM\LLM-Kit\app\components\services\parse_service.py", line 302, in parse_content
    raise Exception(f"Parse content failed: {str(e)}")
Exception: Parse content failed: [WinError 183] 当文件已存在时，无法创建该文件。: './parsed_files\\parsed_file\\tmpdv65ytd6.txt' -> './parsed_files\\parsed_file\\test003_parsed.txt'
2025-01-26 14:55:58,515 - app.components.routers.to_tex - ERROR - 删除LaTeX记录失败 record_id: 6795dc181e957ef81ff27019, 错误: 404: Record not found
Traceback (most recent call last):
  File "D:\problem_solve\Python\Final_LLM\LLM-Kit\app\components\routers\to_tex.py", line 140, in delete_tex_record
    raise HTTPException(status_code=404, detail="Record not found")
fastapi.exceptions.HTTPException: 404: Record not found
2025-01-26 14:56:02,736 - app.components.routers.to_tex - ERROR - 获取进度失败: 404: Record not found
Traceback (most recent call last):
  File "D:\problem_solve\Python\Final_LLM\LLM-Kit\app\components\routers\to_tex.py", line 113, in get_tex_progress
    raise HTTPException(status_code=404, detail="Record not found")
fastapi.exceptions.HTTPException: 404: Record not found
2025-01-26 14:58:02,603 - app.components.routers.qa_generate - ERROR - 生成问答对失败: Expecting value: line 1 column 1 (char 0)
Traceback (most recent call last):
  File "D:\problem_solve\Python\Final_LLM\LLM-Kit\app\components\routers\qa_generate.py", line 78, in generate_qa_pairs
    result = await service.generate_qa_pairs(
             ^^^^^^^^^^^^^^^^^^^^^^^^^^^^^^^^
  File "D:\problem_solve\Python\Final_LLM\LLM-Kit\app\components\services\qa_generate_service.py", line 330, in generate_qa_pairs
    raise e
  File "D:\problem_solve\Python\Final_LLM\LLM-Kit\app\components\services\qa_generate_service.py", line 212, in generate_qa_pairs
    chunks = json.loads(content)
             ^^^^^^^^^^^^^^^^^^^
  File "D:\Python\Lib\json\__init__.py", line 346, in loads
    return _default_decoder.decode(s)
           ^^^^^^^^^^^^^^^^^^^^^^^^^^
  File "D:\Python\Lib\json\decoder.py", line 337, in decode
    obj, end = self.raw_decode(s, idx=_w(s, 0).end())
               ^^^^^^^^^^^^^^^^^^^^^^^^^^^^^^^^^^^^^^
  File "D:\Python\Lib\json\decoder.py", line 355, in raw_decode
    raise JSONDecodeError("Expecting value", s, err.value) from None
json.decoder.JSONDecodeError: Expecting value: line 1 column 1 (char 0)
2025-01-26 15:06:56,082 - app.components.routers.qa_generate - ERROR - 生成问答对失败: Expecting value: line 1 column 1 (char 0)
Traceback (most recent call last):
  File "D:\problem_solve\Python\Final_LLM\LLM-Kit\app\components\routers\qa_generate.py", line 78, in generate_qa_pairs
    result = await service.generate_qa_pairs(
             ^^^^^^^^^^^^^^^^^^^^^^^^^^^^^^^^
  File "D:\problem_solve\Python\Final_LLM\LLM-Kit\app\components\services\qa_generate_service.py", line 330, in generate_qa_pairs
    raise e
  File "D:\problem_solve\Python\Final_LLM\LLM-Kit\app\components\services\qa_generate_service.py", line 212, in generate_qa_pairs
    chunks = json.loads(content)
             ^^^^^^^^^^^^^^^^^^^
  File "D:\Python\Lib\json\__init__.py", line 346, in loads
    return _default_decoder.decode(s)
           ^^^^^^^^^^^^^^^^^^^^^^^^^^
  File "D:\Python\Lib\json\decoder.py", line 337, in decode
    obj, end = self.raw_decode(s, idx=_w(s, 0).end())
               ^^^^^^^^^^^^^^^^^^^^^^^^^^^^^^^^^^^^^^
  File "D:\Python\Lib\json\decoder.py", line 355, in raw_decode
    raise JSONDecodeError("Expecting value", s, err.value) from None
json.decoder.JSONDecodeError: Expecting value: line 1 column 1 (char 0)
